Workbook

Sheet PL
A1: Sno | B1: Date | C1: Month | D1: Year | E1: Deal Wins(N) | F1: Contract | G1: MOM-Growth | H1: Income | I1: Expense | J1: Profit | K1: MOM-Growth
A2: 1 | B2: 45901 | C2: =TEXT(B2,"mmmm") -> September | D2: =YEAR(B2) -> 2025 | E2: =COUNTIFS('Order Book'!C:C,">="&B2,'Order Book'!C:C,"<="&EOMONTH(B2,0)) -> 6 | F2: =SUMIFS('Order Book'!M:M,'Order Book'!C:C,">="&B2,'Order Book'!C:C,"<="&EOMONTH(B2,0)) -> 460000 | H2: =SUMIFS(Income!K:K,Income!C:C,">="&B2,Income!C:C,"<="&EOMONTH(B2,0)) -> 85000 | I2: =SUMIFS(Expenses!G:G,Expenses!B:B,">="&B2,Expenses!B:B,"<="&EOMONTH(B2,0)) -> 96060.63 | J2: =H2-I2 -> -11060.63
A3: =A2+1 -> 2 | B3: 45931 | C3: =TEXT(B3,"mmmm") -> October | D3: =YEAR(B3) -> 2025 | E3: =COUNTIFS('Order Book'!C:C,">="&B3,'Order Book'!C:C,"<="&EOMONTH(B3,0)) -> 7 | F3: =SUMIFS('Order Book'!M:M,'Order Book'!C:C,">="&B3,'Order Book'!C:C,"<="&EOMONTH(B3,0)) -> 1075500 | G3: =IFERROR(ABS(F3/F2)-1,0) -> 1.3380435 | H3: =SUMIFS(Income!K:K,Income!C:C,">="&B3,Income!C:C,"<="&EOMONTH(B3,0)) -> 397500 | I3: =SUMIFS(Expenses!G:G,Expenses!B:B,">="&B3,Expenses!B:B,"<="&EOMONTH(B3,0)) -> 337681.02 | J3: =H3-I3 -> 59818.98 | K3: =IFERROR(ABS(J3/J2)-1,0) -> 4.4082796
A4: =A3+1 -> 3 | B4: 45962 | C4: =TEXT(B4,"mmmm") -> November | D4: =YEAR(B4) -> 2025 | E4: =COUNTIFS('Order Book'!C:C,">="&B4,'Order Book'!C:C,"<="&EOMONTH(B4,0)) -> 9 | F4: =SUMIFS('Order Book'!M:M,'Order Book'!C:C,">="&B4,'Order Book'!C:C,"<="&EOMONTH(B4,0)) -> 1307500 | G4: =IFERROR(ABS(F4/F3)-1,0) -> 0.21571362 | H4: =SUMIFS(Income!K:K,Income!C:C,">="&B4,Income!C:C,"<="&EOMONTH(B4,0)) -> 666838.42 | I4: =SUMIFS(Expenses!G:G,Expenses!B:B,">="&B4,Expenses!B:B,"<="&EOMONTH(B4,0)) -> 415195.03 | J4: =H4-I4 -> 251643.39 | K4: =IFERROR(ABS(J4/J3)-1,0) -> 3.2067483
A5: =A4+1 -> 4 | B5: 45992 | C5: =TEXT(B5,"mmmm") -> December | D5: =YEAR(B5) -> 2025 | E5: =COUNTIFS('Order Book'!C:C,">="&B5,'Order Book'!C:C,"<="&EOMONTH(B5,0)) -> 7 | F5: =SUMIFS('Order Book'!M:M,'Order Book'!C:C,">="&B5,'Order Book'!C:C,"<="&EOMONTH(B5,0)) -> 730000 | G5: =IFERROR(ABS(F5/F4)-1,0) -> -0.4416826 | H5: =SUMIFS(Income!K:K,Income!C:C,">="&B5,Income!C:C,"<="&EOMONTH(B5,0)) -> 587000 | I5: =SUMIFS(Expenses!G:G,Expenses!B:B,">="&B5,Expenses!B:B,"<="&EOMONTH(B5,0)) -> 382480.84 | J5: =H5-I5 -> 204519.16 | K5: =IFERROR(ABS(J5/J4)-1,0) -> -0.18726591
A6: =A5+1 -> 5 | B6: 46023 | C6: =TEXT(B6,"mmmm") -> January | D6: =YEAR(B6) -> 2026 | E6: =COUNTIFS('Order Book'!C:C,">="&B6,'Order Book'!C:C,"<="&EOMONTH(B6,0)) -> 2 | F6: =SUMIFS('Order Book'!M:M,'Order Book'!C:C,">="&B6,'Order Book'!C:C,"<="&EOMONTH(B6,0)) -> 145000 | G6: =IFERROR(ABS(F6/F5)-1,0) -> -0.80136986 | H6: =SUMIFS(Income!K:K,Income!C:C,">="&B6,Income!C:C,"<="&EOMONTH(B6,0)) -> 284500 | I6: =SUMIFS(Expenses!G:G,Expenses!B:B,">="&B6,Expenses!B:B,"<="&EOMONTH(B6,0)) -> 326461.51 | J6: =H6-I6 -> -41961.51 | K6: =IFERROR(ABS(J6/J5)-1,0) -> -0.79482847
A7: =A6+1 -> 6 | B7: 46054 | C7: =TEXT(B7,"mmmm") -> February | D7: =YEAR(B7) -> 2026 | E7: =COUNTIFS('Order Book'!C:C,">="&B7,'Order Book'!C:C,"<="&EOMONTH(B7,0)) -> 7 | F7: =SUMIFS('Order Book'!M:M,'Order Book'!C:C,">="&B7,'Order Book'!C:C,"<="&EOMONTH(B7,0)) -> 894510 | G7: =IFERROR(ABS(F7/F6)-1,0) -> 5.1690345 | H7: =SUMIFS(Income!K:K,Income!C:C,">="&B7,Income!C:C,"<="&EOMONTH(B7,0)) -> 646383.9 | I7: =SUMIFS(Expenses!G:G,Expenses!B:B,">="&B7,Expenses!B:B,"<="&EOMONTH(B7,0)) -> 461834.11 | J7: =H7-I7 -> 184549.79 | K7: =IFERROR(ABS(J7/J6)-1,0) -> 3.3980731
A8: =A7+1 -> 7 | B8: 46082 | C8: =TEXT(B8,"mmmm") -> March | D8: =YEAR(B8) -> 2026 | E8: =COUNTIFS('Order Book'!C:C,">="&B8,'Order Book'!C:C,"<="&EOMONTH(B8,0)) -> 1 | F8: =SUMIFS('Order Book'!M:M,'Order Book'!C:C,">="&B8,'Order Book'!C:C,"<="&EOMONTH(B8,0)) -> 95000 | G8: =IFERROR(ABS(F8/F7)-1,0) -> -0.8937966 | H8: =SUMIFS(Income!K:K,Income!C:C,">="&B8,Income!C:C,"<="&EOMONTH(B8,0)) -> 105000 | I8: =SUMIFS(Expenses!G:G,Expenses!B:B,">="&B8,Expenses!B:B,"<="&EOMONTH(B8,0)) -> 420064.18 | J8: =H8-I8 -> -315064.18 | K8: =IFERROR(ABS(J8/J7)-1,0) -> 0.70720422
A9: =A8+1 -> 8 | B9: 46113 | C9: =TEXT(B9,"mmmm") -> April | D9: =YEAR(B9) -> 2026 | E9: =COUNTIFS('Order Book'!C:C,">="&B9,'Order Book'!C:C,"<="&EOMONTH(B9,0)) -> 0 | F9: =SUMIFS('Order Book'!M:M,'Order Book'!C:C,">="&B9,'Order Book'!C:C,"<="&EOMONTH(B9,0)) -> 0 | G9: =IFERROR(ABS(F9/F8)-1,0) -> -1 | H9: =SUMIFS(Income!K:K,Income!C:C,">="&B9,Income!C:C,"<="&EOMONTH(B9,0)) -> 0 | I9: =SUMIFS(Expenses!G:G,Expenses!B:B,">="&B9,Expenses!B:B,"<="&EOMONTH(B9,0)) -> 0 | J9: =H9-I9 -> 0 | K9: =IFERROR(ABS(J9/J8)-1,0) -> -1
A10: =A9+1 -> 9 | B10: 46143 | C10: =TEXT(B10,"mmmm") -> May | D10: =YEAR(B10) -> 2026 | E10: =COUNTIFS('Order Book'!C:C,">="&B10,'Order Book'!C:C,"<="&EOMONTH(B10,0)) -> 0 | F10: =SUMIFS('Order Book'!M:M,'Order Book'!C:C,">="&B10,'Order Book'!C:C,"<="&EOMONTH(B10,0)) -> 0 | G10: =IFERROR(ABS(F10/F9)-1,0) -> 0 | H10: =SUMIFS(Income!K:K,Income!C:C,">="&B10,Income!C:C,"<="&EOMONTH(B10,0)) -> 0 | I10: =SUMIFS(Expenses!G:G,Expenses!B:B,">="&B10,Expenses!B:B,"<="&EOMONTH(B10,0)) -> 0 | J10: =H10-I10 -> 0 | K10: =IFERROR(ABS(J10/J9)-1,0) -> 0
A11: =A10+1 -> 10 | B11: 46174 | C11: =TEXT(B11,"mmmm") -> June | D11: =YEAR(B11) -> 2026 | E11: =COUNTIFS('Order Book'!C:C,">="&B11,'Order Book'!C:C,"<="&EOMONTH(B11,0)) -> 0 | F11: =SUMIFS('Order Book'!M:M,'Order Book'!C:C,">="&B11,'Order Book'!C:C,"<="&EOMONTH(B11,0)) -> 0 | G11: =IFERROR(ABS(F11/F10)-1,0) -> 0 | H11: =SUMIFS(Income!K:K,Income!C:C,">="&B11,Income!C:C,"<="&EOMONTH(B11,0)) -> 0 | I11: =SUMIFS(Expenses!G:G,Expenses!B:B,">="&B11,Expenses!B:B,"<="&EOMONTH(B11,0)) -> 0 | J11: =H11-I11 -> 0 | K11: =IFERROR(ABS(J11/J10)-1,0) -> 0
A12: =A11+1 -> 11 | B12: 46204 | C12: =TEXT(B12,"mmmm") -> July | D12: =YEAR(B12) -> 2026 | E12: =COUNTIFS('Order Book'!C:C,">="&B12,'Order Book'!C:C,"<="&EOMONTH(B12,0)) -> 0 | F12: =SUMIFS('Order Book'!M:M,'Order Book'!C:C,">="&B12,'Order Book'!C:C,"<="&EOMONTH(B12,0)) -> 0 | G12: =IFERROR(ABS(F12/F11)-1,0) -> 0 | H12: =SUMIFS(Income!K:K,Income!C:C,">="&B12,Income!C:C,"<="&EOMONTH(B12,0)) -> 0 | I12: =SUMIFS(Expenses!G:G,Expenses!B:B,">="&B12,Expenses!B:B,"<="&EOMONTH(B12,0)) -> 0 | J12: =H12-I12 -> 0 | K12: =IFERROR(ABS(J12/J11)-1,0) -> 0
A13: =A12+1 -> 12 | B13: 46235 | C13: =TEXT(B13,"mmmm") -> August | D13: =YEAR(B13) -> 2026 | E13: =COUNTIFS('Order Book'!C:C,">="&B13,'Order Book'!C:C,"<="&EOMONTH(B13,0)) -> 0 | F13: =SUMIFS('Order Book'!M:M,'Order Book'!C:C,">="&B13,'Order Book'!C:C,"<="&EOMONTH(B13,0)) -> 0 | G13: =IFERROR(ABS(F13/F12)-1,0) -> 0 | H13: =SUMIFS(Income!K:K,Income!C:C,">="&B13,Income!C:C,"<="&EOMONTH(B13,0)) -> 0 | I13: =SUMIFS(Expenses!G:G,Expenses!B:B,">="&B13,Expenses!B:B,"<="&EOMONTH(B13,0)) -> 0 | J13: =H13-I13 -> 0 | K13: =IFERROR(ABS(J13/J12)-1,0) -> 0
A14: =A13+1 -> 13 | B14: 46266 | C14: =TEXT(B14,"mmmm") -> September | D14: =YEAR(B14) -> 2026 | E14: =COUNTIFS('Order Book'!C:C,">="&B14,'Order Book'!C:C,"<="&EOMONTH(B14,0)) -> 0 | F14: =SUMIFS('Order Book'!M:M,'Order Book'!C:C,">="&B14,'Order Book'!C:C,"<="&EOMONTH(B14,0)) -> 0 | G14: =IFERROR(ABS(F14/F13)-1,0) -> 0 | H14: =SUMIFS(Income!K:K,Income!C:C,">="&B14,Income!C:C,"<="&EOMONTH(B14,0)) -> 0 | I14: =SUMIFS(Expenses!G:G,Expenses!B:B,">="&B14,Expenses!B:B,"<="&EOMONTH(B14,0)) -> 0 | J14: =H14-I14 -> 0 | K14: =IFERROR(ABS(J14/J13)-1,0) -> 0
... A17: =A16+1 -> 16 | B17: 46357 | C17: =TEXT(B17,"mmmm") -> December | D17: =YEAR(B17) -> 2026 | E17: =COUNTIFS('Order Book'!C:C,">="&B17,'Order Book'!C:C,"<="&EOMONTH(B17,0)) -> 0 | F17: =SUMIFS('Order Book'!M:M,'Order Book'!C:C,">="&B17,'Order Book'!C:C,"<="&EOMONTH(B17,0)) -> 0 | G17: =IFERROR(ABS(F17/F16)-1,0) -> 0 | H17: =SUMIFS(Income!K:K,Income!C:C,">="&B17,Income!C:C,"<="&EOMONTH(B17,0)) -> 0 | I17: =SUMIFS(Expenses!G:G,Expenses!B:B,">="&B17,Expenses!B:B,"<="&EOMONTH(B17,0)) -> 0 | J17: =H17-I17 -> 0 | K17: =IFERROR(ABS(J17/J16)-1,0) -> 0
C19: Total | E19: =SUM(E2:E17) -> 39 | F19: =SUM(F2:F17) -> 4707510
C20: Pending Amount | F20: =F19-H20 -> 1935287.7 | H20: =SUM(H2:H17) -> 2772222.3 | I20: =SUM(I2:I17) -> 2439777.3 | J20: =SUM(J2:J17) -> 332445

Sheet How to
A1: ArgosMob Tech & AI Pvt LTD, Feb 2026, P/L Distribution
A2: Total profit | B2: =PL!J7+125000 -> 309549.79
A3: Director Salary | B3: 125000
A4: Monthly expenses Adjustments | B4: 4259.78
A5: Net Profit | B5: =B2-B3-B4 -> 180290.01
A7: Profit/Partner | B7: =B5/5 -> 36058.002
A8: Salary+Profit | B8: =B7+25000 -> 61058.002
A13: 46054 | B13: Salary | C13: Adjustment | D13: Profit | E13: Settlement Amout | F13: Total
A14: Chandan | B14: 25000 | C14: =Expenses!P2 -> 30882 | D14: =$B$7 -> 36058.002 | E14: =D14-C14 -> 5176.002 | F14: =D14+B14 -> 61058.002
A15: Krishan | B15: 25000 | C15: =Expenses!P3 -> 44061.18 | D15: =$B$7 -> 36058.002 | E15: =D15-C15 -> -8003.178 | F15: =D15+B15 -> 61058.002
A16: Rishab | B16: 25000 | C16: =Expenses!P4 -> 48151.98 | D16: =$B$7 -> 36058.002 | E16: =D16-C16 -> -12093.978 | F16: =D16+B16 -> 61058.002
A17: Vansh | B17: 25000 | C17: =Expenses!P5 -> 31058 | D17: =$B$7 -> 36058.002 | E17: =D17-C17 -> 5000.002 | F17: =D17+B17 -> 61058.002
A18: Dr Chadha | B18: 12500 | D18: =D17/2 -> 18029.001 | E18: =D18-C18 -> 18029.001 | F18: =D18+B18 -> 30529.001
A19: Jitender sir | B19: 12500 | D19: =D18 -> 18029.001 | E19: =D19-C19 -> 18029.001 | F19: =D19+B19 -> 30529.001
A21: Total | B21: =SUM(B14:B19) -> 125000 | C21: =SUM(C14:C19) -> 154153.16 | D21: =SUM(D14:D19) -> 180290.01 | E21: =SUM(E14:E19) -> 26136.85 | F21: =SUM(F14:F19) -> 305290.01

Sheet Daily Tracker
A1: Sno | B1: Week Number | C1: Day | D1: Date | E1: Revenue | F1: Expenses | G1: New Orders | H1: Change in old project
A2: 1 | B2: =WEEKNUM(D2) -> 5 | C2: =TEXT(D2,"dddd") -> Tuesday | D2: 46049 | E2: =SUMIFS(Income!K:K,Income!C:C,'Daily Tracker'!D2) -> 50000 | F2: =SUMIFS(Expenses!G:G,Expenses!B:B,'Daily Tracker'!D2) -> 47191.47 | G2: =SUMIFS('Order Book'!K:K,'Order Book'!C:C,'Daily Tracker'!D2) -> 0
A3: 2 | B3: =WEEKNUM(D3) -> 5 | C3: =TEXT(D3,"dddd") -> Wednesday | D3: 46050 | E3: =SUMIFS(Income!K:K,Income!C:C,'Daily Tracker'!D3) -> 0 | F3: =SUMIFS(Expenses!G:G,Expenses!B:B,'Daily Tracker'!D3) -> 0 | G3: =SUMIFS('Order Book'!K:K,'Order Book'!C:C,'Daily Tracker'!D3) -> 0
A4: 3 | B4: =WEEKNUM(D4) -> 5 | C4: =TEXT(D4,"dddd") -> Thursday | D4: 46051 | E4: =SUMIFS(Income!K:K,Income!C:C,'Daily Tracker'!D4) -> 0 | F4: =SUMIFS(Expenses!G:G,Expenses!B:B,'Daily Tracker'!D4) -> 6235 | G4: =SUMIFS('Order Book'!K:K,'Order Book'!C:C,'Daily Tracker'!D4) -> 0
A5: 4 | B5: =WEEKNUM(D5) -> 5 | C5: =TEXT(D5,"dddd") -> Friday | D5: 46052 | E5: =SUMIFS(Income!K:K,Income!C:C,'Daily Tracker'!D5) -> 0 | F5: =SUMIFS(Expenses!G:G,Expenses!B:B,'Daily Tracker'!D5) -> 36727 | G5: =SUMIFS('Order Book'!K:K,'Order Book'!C:C,'Daily Tracker'!D5) -> 0
A6: 5 | B6: =WEEKNUM(D6) -> 5 | C6: =TEXT(D6,"dddd") -> Saturday | D6: 46053 | E6: =SUMIFS(Income!K:K,Income!C:C,'Daily Tracker'!D6) -> 0 | F6: =SUMIFS(Expenses!G:G,Expenses!B:B,'Daily Tracker'!D6) -> 1256.58 | G6: =SUMIFS('Order Book'!K:K,'Order Book'!C:C,'Daily Tracker'!D6) -> 0
A7: 6 | B7: =WEEKNUM(D7) -> 6 | C7: =TEXT(D7,"dddd") -> Sunday | D7: 46054 | E7: =SUMIFS(Income!K:K,Income!C:C,'Daily Tracker'!D7) -> 0 | F7: =SUMIFS(Expenses!G:G,Expenses!B:B,'Daily Tracker'!D7) -> 0 | G7: =SUMIFS('Order Book'!K:K,'Order Book'!C:C,'Daily Tracker'!D7) -> 0
A8: 7 | B8: =WEEKNUM(D8) -> 6 | C8: =TEXT(D8,"dddd") -> Monday | D8: 46055 | E8: =SUMIFS(Income!K:K,Income!C:C,'Daily Tracker'!D8) -> 75000 | F8: =SUMIFS(Expenses!G:G,Expenses!B:B,'Daily Tracker'!D8) -> 14029.6 | G8: =SUMIFS('Order Book'!K:K,'Order Book'!C:C,'Daily Tracker'!D8) -> 400000
A9: 8 | B9: =WEEKNUM(D9) -> 6 | C9: =TEXT(D9,"dddd") -> Tuesday | D9: 46056 | E9: =SUMIFS(Income!K:K,Income!C:C,'Daily Tracker'!D9) -> 0 | F9: =SUMIFS(Expenses!G:G,Expenses!B:B,'Daily Tracker'!D9) -> 349 | G9: =SUMIFS('Order Book'!K:K,'Order Book'!C:C,'Daily Tracker'!D9) -> 0
A10: 9 | B10: =WEEKNUM(D10) -> 6 | C10: =TEXT(D10,"dddd") -> Wednesday | D10: 46057 | E10: =SUMIFS(Income!K:K,Income!C:C,'Daily Tracker'!D10) -> 0 | F10: =SUMIFS(Expenses!G:G,Expenses!B:B,'Daily Tracker'!D10) -> 590 | G10: =SUMIFS('Order Book'!K:K,'Order Book'!C:C,'Daily Tracker'!D10) -> 25000
A11: 10 | B11: =WEEKNUM(D11) -> 6 | C11: =TEXT(D11,"dddd") -> Thursday | D11: 46058 | E11: =SUMIFS(Income!K:K,Income!C:C,'Daily Tracker'!D11) -> 0 | F11: =SUMIFS(Expenses!G:G,Expenses!B:B,'Daily Tracker'!D11) -> 25300 | G11: =SUMIFS('Order Book'!K:K,'Order Book'!C:C,'Daily Tracker'!D11) -> 50000
A12: 11 | B12: =WEEKNUM(D12) -> 6 | C12: =TEXT(D12,"dddd") -> Friday | D12: 46059 | E12: =SUMIFS(Income!K:K,Income!C:C,'Daily Tracker'!D12) -> 25000 | F12: =SUMIFS(Expenses!G:G,Expenses!B:B,'Daily Tracker'!D12) -> 350 | G12: =SUMIFS('Order Book'!K:K,'Order Book'!C:C,'Daily Tracker'!D12) -> 0
A13: 12 | B13: =WEEKNUM(D13) -> 6 | C13: =TEXT(D13,"dddd") -> Saturday | D13: 46060 | E13: =SUMIFS(Income!K:K,Income!C:C,'Daily Tracker'!D13) -> 30000 | F13: =SUMIFS(Expenses!G:G,Expenses!B:B,'Daily Tracker'!D13) -> 4517.7 | G13: =SUMIFS('Order Book'!K:K,'Order Book'!C:C,'Daily Tracker'!D13) -> 0
... A66: 65 | B66: =WEEKNUM(D66) -> 14 | C66: =TEXT(D66,"dddd") -> Wednesday | D66: 46113 | E66: =SUMIFS(Income!K:K,Income!C:C,'Daily Tracker'!D66) -> 0 | F66: =SUMIFS(Expenses!G:G,Expenses!B:B,'Daily Tracker'!D66) -> 0 | G66: =SUMIFS('Order Book'!K:K,'Order Book'!C:C,'Daily Tracker'!D66) -> 0

Sheet Staff
A1: Sno | B1: Team | C1: Name | D1: Salary | E1: Location | F1: Comments | G1: DOJ
A2: 1 | B2: HR | C2: Ravleen Kaur | D2: 15000 | E2: Office | G2: DOJ- 27-1-2026 | H2: 17500
A3: 2 | B3: Mobile | C3: Prashant | D3: 15000 | E3: Office | F3: DOJ- 28-10-2025 | G3: 45958 | H3: 12000
A4: 3 | B4: Mobile | C4: Aditya Jain | D4: 31000 | E4: Office | F4: DOJ- 27-1-2026 | G4: DOJ- 27-1-2026 | H4: 35000
A5: 4 | B5: Mobile | C5: Ishika Sharma | D5: 25000 | E5: Office | H5: 25000
A6: 5 | B6: Mobile | C6: Shubham Dubey | D6: 15000 | E6: Office | H6: 10000
A7: 6 | B7: Sales | C7: Haider | D7: 45000 | E7: Office | F7: DOJ- 27-10-2025 | G7: 45909 | H7: 45000
A8: 7 | B8: Sales | C8: Avani Shree | D8: 30000 | E8: Office | G8: 46069 | H8: 13000
A9: 8 | B9: Mobile+Back End | C9: Priyanka | D9: 30000 | E9: Office | F9: DOJ- 10-11-2025 | G9: 45894 | H9: 30000
A10: 9 | B10: Web - Back end | C10: Dev kumar Sharma | D10: 40000 | E10: WFH | G10: 45957 | H10: 40000
A11: 10 | B11: Video Editor | C11: Resource 1 | E11: Office
A12: 11 | B12: Tester | C12: Ranjeet | D12: 20000 | E12: Office | G12: 46090
A13: 12 | B13: Sales | C13: Akansha Giri | D13: 33000 | E13: Office | H13: 15000
A14: 13 | B14: Sales | C14: Yash Vohra | D14: 0 | E14: WFH
A15: 14 | B15: Sales | C15: Asmita Pandey | D15: 45000 | E15: Office | G15: 46093
C26: Total Salary | D26: =SUM(D2:D15) -> 344000 | E26: 240000
C27: Office rent | D27: 32000 | E27: 32000
C28: Misc | D28: 18000 | E28: 18000
C29: Marketing | D29: 180000
C30: IT subscriptions | D30: 4000
C33: Total Monthly Expenses | D33: =SUM(D26:D30) -> 578000 | F33: =D33+125000 -> 703000
C34: Annual Expenses | D34: =D33*12 -> 6936000 | E34: 50lac | F34: =F33/0.4 -> 1757500
C35: Per partner Expenses | D35: =D33/4 -> 144500

Sheet Feb expenses
A1: Feb Expenses
A2: Sno | B2: Team | C2: Name | D2: Salary | E2: Location | F2: DOJ
A3: 1 | B3: Mobile | C3: Prashant | D3: 10000 | E3: Office
A4: =A3+1 -> 2 | B4: Mobile | C4: Ishika Sharma | D4: =G4/30*25000 -> 14166.667 | E4: Office | F4: 46036 | G4: =_xlfn.DAYS(H4,F4) -> 17 | H4: 46053
A5: =A4+1 -> 3 | B5: Mobile | C5: Shubham Dubey | D5: =G5/30*10000 -> 8666.6667 | E5: Office | F5: 46027 | G5: =_xlfn.DAYS(H5,F5) -> 26 | H5: 46053
A6: =A5+1 -> 4 | B6: Mobile | C6: Aditya | D6: 0 | E6: Office
A7: =A6+1 -> 5 | B7: Mobile | C7: Anoop | D7: =G7/30*15000 -> 7500 | E7: Office | F7: 46038 | G7: =_xlfn.DAYS(H7,F7) -> 15 | H7: 46053
A8: =A7+1 -> 6 | B8: HR | C8: Prachi Lohani | D8: 25000 | E8: Office
A9: =A8+1 -> 7 | B9: Sales | C9: Ishika Rawal | D9: 0 | E9: Office
A10: =A9+1 -> 8 | B10: Sales | C10: Resource 2 | E10: Office
A11: =A10+1 -> 9 | B11: Sales | C11: Haider | D11: 37500 | E11: Office
A12: =A11+1 -> 10 | B12: Testing | C12: Resource 3 | E12: Office
A13: =A12+1 -> 11 | B13: Web - Back end | C13: Priyanka | D13: 30000 | E13: Office
A14: =A13+1 -> 12 | B14: Web - Back end | C14: Dev kumar Sharma | D14: 40000 | E14: WFH
C17: Total Salary | D17: =SUM(D3:D15) -> 172833.33
C18: Office rent | D18: 32000
C19: Misc | D19: 18000
C20: Marketing | D20: 180000
C21: IT subscriptions | D21: 4000
C24: Total Monthly Expenses | D24: =SUM(D17:D21) -> 406833.33
C25: Annual Expenses | D25: =D24*12 -> 4882000
C26: Per partner Expenses | D26: =D24/4 -> 101708.33

Sheet Income(International)
A1: Sno | B1: Day | C1: Date | D1: Project | E1: Sale | F1: Currency | G1: Mode | H1: Project | I1: Client Name | J1: Country

Sheet Income
A1: Sno | B1: Day | C1: Date | D1: Type of Sale | E1: Project Type | F1: Resource | G1: Project Name | H1: Client Name | I1: Country | J1: State | K1: Sale | L1: Currency | M1: Income Receiver | N1: Mode | P1: Row Labels | Q1: Sum of Sale
A2: 1 | B2: =TEXT(C2,"dddd") -> Monday | C2: 45908 | D2: New Acquisition | E2: Android+IOS App | F2: N/A | G2: Employee India | H2: Taufeeq | I2: India | J2: Uttar Pradesh | K2: 25000 | L2: 1 | M2: Chandan | N2: Axis Bank UPI | P2: Parul Sandilya | Q2: 658500
A3: =A2+1 -> 2 | B3: =TEXT(C3,"dddd") -> Tuesday | C3: 45916 | D3: New Acquisition | E3: Android App | F3: Prachi Lohani | G3: Makroo | H3: Umar | I3: India | J3: Jammu | K3: 30000 | L3: 1 | M3: Account-ArgosMob | N3: PhonePe | P3: Prachi Lohani | Q3: 640001
A4: =A3+1 -> 3 | B4: =TEXT(C4,"dddd") -> Sunday | C4: 45921 | D4: New Acquisition | E4: AI | F4: Parul Sandilya | G4: AI | H4: Sushil | I4: India | J4: Uttar Pradesh | K4: 20000 | L4: 1 | M4: Chandan | N4: Axis Bank UPI | P4: Haider | Q4: 530500
A5: =A4+1 -> 4 | B5: =TEXT(C5,"dddd") -> Friday | C5: 45926 | D5: New Acquisition | E5: Website | F5: N/A | G5: Healthy Manushya | H5: Arun Sharma | I5: India | J5: Punjab | K5: 10000 | L5: 1 | M5: Account-ArgosMob | N5: Net Banking | P5: N/A | Q5: 321837.42
A6: =A5+1 -> 5 | B6: =TEXT(C6,"dddd") -> Wednesday | C6: 45931 | D6: New Acquisition | E6: Android+IOS App+Website | F6: Prachi Lohani | G6: MediConnect | H6: Brij | I6: India | J6: Haryana | K6: 99000 | L6: 1 | M6: Account-ArgosMob | N6: UPI | P6: Grand Total | Q6: 2150838.4
A7: =A6+1 -> 6 | B7: =TEXT(C7,"dddd") -> Thursday | C7: 45932 | D7: New Acquisition | E7: Android+IOS App+Website | F7: Prachi Lohani | G7: MediConnect | H7: Brij | I7: India | J7: Haryana | K7: 81000 | L7: 1 | M7: Account-ArgosMob | N7: UPI
A8: =A7+1 -> 7 | B8: =TEXT(C8,"dddd") -> Friday | C8: 45933 | D8: Old Acquisition | E8: Android App | F8: Prachi Lohani | G8: Makroo | H8: Umar | I8: India | J8: Jammu | K8: 30000 | L8: 1 | M8: Account-ArgosMob | N8: PhonePe
A9: =A8+1 -> 8 | B9: =TEXT(C9,"dddd") -> Friday | C9: 45940 | D9: New Acquisition | E9: Android+IOS App | F9: Prachi Lohani | G9: Fornix | H9: Venket | I9: India | J9: Karnataka | K9: 40000 | L9: 1 | M9: Account-ArgosMob | N9: UPI
A10: =A9+1 -> 9 | B10: =TEXT(C10,"dddd") -> Monday | C10: 45943 | D10: Old Acquisition | E10: Android+IOS App | F10: N/A | G10: Employee India | H10: Taufeeq | I10: India | J10: Uttar Pradesh | K10: 25000 | L10: 1 | M10: Cash | N10: Cash
A11: =A10+1 -> 10 | B11: =TEXT(C11,"dddd") -> Tuesday | C11: 45944 | D11: New Acquisition | E11: AI | F11: N/A | G11: Stenna | H11: Madhur Goel | I11: India | J11: Delhi | K11: 20000 | L11: 1 | M11: Account-ArgosMob | N11: Net Banking
A12: =A11+1 -> 11 | B12: =TEXT(C12,"dddd") -> Thursday | C12: 45946 | D12: New Acquisition | E12: Android+IOS App | F12: Parul Sandilya | G12: Bla-Bla | H12: Prem Reddy | I12: India | J12: Karnataka | K12: 15000 | L12: 1 | M12: Account-ArgosMob | N12: UPI
A13: =A12+1 -> 12 | B13: =TEXT(C13,"dddd") -> Friday | C13: 45947 | D13: New Acquisition | E13: Android+IOS App | F13: Parul Sandilya | G13: Bhardwaj hospital | H13: Dr Arun | I13: India | J13: Uttar Pradesh | K13: 22500 | L13: 1 | M13: Account-ArgosMob | N13: UPI
A14: =A13+1 -> 13 | B14: =TEXT(C14,"dddd") -> Friday | C14: 45947 | D14: New Acquisition | E14: Android+IOS App | F14: Parul Sandilya | G14: Eco Volt Solar | H14: Kuldeep | I14: India | J14: Uttar Pradesh | K14: 40000 | L14: 1 | M14: Account-ArgosMob | N14: Net Banking
A15: =A14+1 -> 14 | B15: =TEXT(C15,"dddd") -> Friday | C15: 45954 | D15: Old Acquisition | E15: AI | F15: Parul Sandilya | G15: AI | H15: Sushil | I15: India | J15: Uttar Pradesh | K15: 20000 | L15: 1 | M15: Chandan | N15: Axis Bank UPI
A16: =A15+1 -> 15 | B16: =TEXT(C16,"dddd") -> Wednesday | C16: 45959 | D16: New Acquisition | E16: Website | F16: N/A | G16: Makroo | H16: Umar | I16: India | J16: Jammu | K16: 5000 | L16: 1 | M16: Account-ArgosMob | N16: PhonePe
A17: =A16+1 -> 16 | B17: =TEXT(C17,"dddd") -> Monday | C17: 45964 | D17: New Acquisition | E17: Android+IOS App | F17: Parul Sandilya | G17: Soya Products-Ecom | H17: M M Mishra | I17: India | J17: Uttar Pradesh | K17: 11000 | L17: 1 | M17: Account-ArgosMob | N17: Net Banking
A18: =A17+1 -> 17 | B18: =TEXT(C18,"dddd") -> Friday | C18: 45968 | D18: Old Acquisition | E18: Android+IOS App+Website | F18: Prachi Lohani | G18: MediConnect | H18: Brij | I18: India | J18: Haryana | K18: 1 | L18: 1 | M18: Account-ArgosMob | N18: UPI
... A32: =A31+1 -> 31 | B32: =TEXT(C32,"dddd") -> Monday | C32: 45985 | D32: New Acquisition | E32: Android+IOS App | F32: Haider | G32: SK Car Finance | H32: Prateek Srivastava | I32: India | J32: Uttar Pradesh | K32: 10000 | L32: 1 | M32: Account-ArgosMob | N32: Axis Bank UPI
A33: =A32+1 -> 32 | B33: =TEXT(C33,"dddd") -> Tuesday | C33: 45986 | D33: New Acquisition | E33: Android+IOS App | F33: N/A | G33: NGK | H33: Strini Naidu | I33: South Africa | K33: 52337.42 | L33: 1 | M33: Chandan | N33: Net Banking
A34: =A33+1 -> 33 | B34: =TEXT(C34,"dddd") -> Thursday | C34: 45988 | D34: New Acquisition | E34: Android+IOS App+Website | F34: Parul Sandilya | G34: Local Market Online | H34: Vinod Khosla | I34: India | J34: Punjab | K34: 80000 | L34: 1 | M34: Account-ArgosMob | N34: Net Banking
A35: =A34+1 -> 34 | B35: =TEXT(C35,"dddd") -> Saturday | C35: 45990 | D35: New Acquisition | E35: Android+IOS App | F35: Haider | G35: School Management App | H35: Amitosh Chaudhary | I35: India | J35: Bihar | K35: 65000 | L35: 1 | M35: Account-ArgosMob | N35: Net Banking
A36: =A35+1 -> 35 | B36: =TEXT(C36,"dddd") -> Monday | C36: 45992 | D36: New Acquisition | E36: Android App | F36: Parul Sandilya | G36: Real estate Data Management | H36: Akash Tripathi | I36: India | J36: Lucknow | K36: 32000 | L36: 1 | M36: Chandan | N36: Gateway
A37: =A36+1 -> 36 | B37: =TEXT(C37,"dddd") -> Tuesday | C37: 45993 | D37: New Acquisition | E37: Android+IOS App+Website | F37: Parul Sandilya | G37: Agriebookhub | H37: Sanjay Kumar | I37: India | J37: Madhya Pradesh | K37: 40000 | L37: 1 | M37: Chandan | N37: Gateway
A38: =A37+1 -> 37 | B38: =TEXT(C38,"dddd") -> Friday | C38: 45996 | D38: New Acquisition | E38: Android+IOS App | F38: Haider | G38: Digital Poster App | H38: Gaurav Shashti | I38: India | J38: Maharashtra | K38: 35000 | L38: 1 | M38: Account-ArgosMob | N38: Net Banking
A39: =A38+1 -> 38 | B39: =TEXT(C39,"dddd") -> Friday | C39: 45996 | D39: Old Acquisition | E39: Android+IOS App | F39: Parul Sandilya | G39: Bla-Bla | H39: Prem Reddy | I39: India | J39: Karnataka | K39: 34000 | L39: 1 | M39: Account-ArgosMob | N39: UPI
A40: =A39+1 -> 39 | B40: =TEXT(C40,"dddd") -> Monday | C40: 45999 | D40: Old Acquisition | E40: Android+IOS App | F40: Haider | G40: Easy Rasta | H40: Dennis Anthony | I40: India | J40: Karnataka | K40: 45000 | L40: 1 | M40: Account-ArgosMob | N40: PhonePe
A41: =A40+1 -> 40 | B41: =TEXT(C41,"dddd") -> Tuesday | C41: 46000 | D41: Old Acquisition | E41: Android+IOS App | F41: Parul Sandilya | G41: FitLeap | H41: Babu Raj | I41: India | J41: West Bengal | K41: 40000 | L41: 1 | M41: Account-ArgosMob | N41: UPI
A42: =A41+1 -> 41 | B42: =TEXT(C42,"dddd") -> Thursday | C42: 46002 | D42: Old Acquisition | E42: Website | F42: N/A | G42: Healthy Manushya | H42: Arun Sharma | I42: India | J42: Punjab | K42: 10000 | L42: 1 | M42: Account-ArgosMob | N42: UPI
A43: =A42+1 -> 42 | B43: =TEXT(C43,"dddd") -> Thursday | C43: 46002 | D43: New Acquisition | E43: Android+IOS App | F43: Haider | G43: Engineered Hybrid Ride-Sharing Platform | H43: Srishylam Jadi | I43: India | J43: Karnataka | K43: 16500 | L43: 1 | M43: Account-ArgosMob | N43: Net Banking
A44: =A43+1 -> 43 | B44: =TEXT(C44,"dddd") -> Monday | C44: 46006 | D44: New Acquisition | E44: Android+IOS App | F44: Parul Sandilya | G44: OTT App | H44: VanLal | I44: India | J44: Mizoram | K44: 50000 | L44: 1 | M44: Account-ArgosMob | N44: Net Banking
A45: =A44+1 -> 44 | B45: =TEXT(C45,"dddd") -> Tuesday | C45: 46007 | D45: Old Acquisition | E45: Android+IOS App | F45: Parul Sandilya | G45: Eco Volt Solar | H45: Kuldeep | I45: India | J45: Uttar Pradesh | K45: 30000 | L45: 1 | M45: Account-ArgosMob | N45: Net Banking
... A58: =A57+1 -> 57 | B58: =TEXT(C58,"dddd") -> Tuesday | C58: 46042 | D58: New Acquisition | E58: Android+IOS App | F58: Haider | G58: Urban Elite | H58: Mahendra | I58: India | J58: Andaman | K58: 10000 | L58: 1 | M58: Account-ArgosMob | N58: Net Banking
A59: =A58+1 -> 58 | B59: =TEXT(C59,"dddd") -> Saturday | C59: 46046 | E59: Android+IOS App | F59: N/A | G59: Degree India | H59: Taufeeq | I59: India | J59: Uttar Pradesh | K59: 15000 | L59: 1 | M59: Chandan | N59: UPI
A60: =A59+1 -> 59 | B60: =TEXT(C60,"dddd") -> Tuesday | C60: 46049 | D60: Old Acquisition | E60: Android+IOS App | F60: Prachi Lohani | G60: Fornix | H60: Venket | I60: India | J60: Karnataka | K60: 40000 | L60: 1 | M60: Rishabh | N60: UPI
A61: =A60+1 -> 60 | B61: =TEXT(C61,"dddd") -> Tuesday | C61: 46049 | D61: Old Acquisition | E61: Website | F61: N/A | G61: Fornix-website | H61: Venket | I61: India | J61: Karnataka | K61: 10000 | L61: 1 | M61: Rishabh | N61: UPI
A62: =A61+1 -> 61 | B62: =TEXT(C62,"dddd") -> Monday | C62: 46055 | D62: Old Acquisition | E62: Android+IOS App+Website | F62: N/A | G62: Local Market Online-AI work | H62: Vinod Khosla | I62: India | J62: Punjab | K62: 25000 | L62: 1 | M62: Account-KiloWatt | N62: Net Banking
A63: =A62+1 -> 62 | B63: =TEXT(C63,"dddd") -> Monday | C63: 46055 | E63: Android+IOS App+Website | F63: N/A | G63: AI LMS Portal | H63: Arun Swamy | I63: India | J63: Rajasthan | K63: 50000 | L63: 1 | M63: Account-KiloWatt | N63: Net Banking
A64: =A63+1 -> 63 | B64: =TEXT(C64,"dddd") -> Friday | C64: 46059 | E64: Website | F64: N/A | G64: Stenna-website | H64: Madhur Goel | I64: India | J64: Delhi | K64: 25000 | L64: 1 | M64: Account-KiloWatt | N64: UPI
A65: =A64+1 -> 64 | B65: =TEXT(C65,"dddd") -> Saturday | C65: 46060 | D65: New Acquisition | E65: Android+IOS App | F65: Haider | G65: Urban Elite | H65: Mahendra | I65: India | J65: Andaman | K65: 30000 | L65: 1 | M65: Account-KiloWatt | N65: Net Banking
...

Sheet Expenses
A1: Sno | B1: Day | C1: Date | D1: Category | E1: Sub-Category | F1: Line Item | G1: Amount | H1: Paid by | I1: Column1 | J1: Person | K1: Income | L1: Expenses | M1: Net | N1: Income(post 28th Jan26) | O1: Expenses( 28th Jan26) | P1: Net | Q1: Account Settlement | S1: Sno | T1: Component | U1: Amount
A2: 1 | B2: 45901 | C2: =TEXT(B2,"dddd") -> Monday | D2: Marketing | E2: FB Ads | F2: FB Budget : 265425466458147 | G2: 1000 | H2: Chandan | J2: Chandan | K2: =SUMIFS(Income!$K:$K,Income!M:M,Expenses!J2,Income!$C:$C,"<="&Validations!$N$1) -> 261337.42 | L2: =SUMIFS(G:G,H:H,J2,B:B,"<="&Validations!$N$1) -> 130143.43 | M2: =K2-L2 -> 131193.99 | N2: =SUMIFS(Income!$K:$K,Income!$M:$M,Expenses!J2,Income!$C:$C,">="&Validations!$N$1) -> 121773.9 | O2: =SUMIFS($G:$G,Expenses!$B:$B,">="&Validations!$N$1,Expenses!$H:$H,Expenses!J2,D:D,"<>"&"Salary") -> 90891.9 | P2: =N2-O2 -> 30882 | Q2: =($L$13+SUM($P$2:$P$5)+$P$9)/5-P2 -> 62565.606 | S2: 1 | T2: Equity | U2: =SUMIFS(G:G,H:H,J9,D:D,T2) -> 433683.33
A3: =A2+1 -> 2 | B3: 45901 | C3: =TEXT(B3,"dddd") -> Monday | D3: Office expense | E3: Chai/Coffee | G3: 80 | H3: Rishabh | J3: Krishna | K3: =SUMIFS(Income!$K:$K,Income!M:M,Expenses!J3,Income!$C:$C,"<="&Validations!$N$1) -> 0 | L3: =SUMIFS(G:G,H:H,J3,B:B,"<="&Validations!$N$1) -> -125530.99 | M3: =K3-L3 -> 125530.99 | N3: =SUMIFS(Income!$K:$K,Income!$M:$M,Expenses!J3,Income!$C:$C,">="&Validations!$N$1) -> 0 | O3: =SUMIFS($G:$G,Expenses!$B:$B,">="&Validations!$N$1,Expenses!$H:$H,Expenses!J3,D:D,"<>"&"Salary") -> -44061.18 | P3: =N3-O3 -> 44061.18 | Q3: =($L$13+SUM($P$2:$P$5)+$P$9)/5-P3 -> 49386.426 | S3: 2 | T3: Loan | U3: =SUMIFS(G:G,H:H,J9,D:D,T3) -> 166816.67
A4: =A3+1 -> 3 | B4: 45901 | C4: =TEXT(B4,"dddd") -> Monday | D4: Office expense | G4: 100 | H4: Rishabh | J4: Rishabh | K4: =SUMIFS(Income!$K:$K,Income!M:M,Expenses!J4,Income!$C:$C,"<="&Validations!$N$1) -> 50000 | L4: =SUMIFS(G:G,H:H,J4,B:B,"<="&Validations!$N$1) -> -75398.993 | M4: =K4-L4 -> 125398.99 | N4: =SUMIFS(Income!$K:$K,Income!$M:$M,Expenses!J4,Income!$C:$C,">="&Validations!$N$1) -> 150000 | O4: =SUMIFS($G:$G,Expenses!$B:$B,">="&Validations!$N$1,Expenses!$H:$H,Expenses!J4,D:D,"<>"&"Salary") -> 101848.02 | P4: =N4-O4 -> 48151.98 | Q4: =($L$13+SUM($P$2:$P$5)+$P$9)/5-P4 -> 45295.626
A5: =A4+1 -> 4 | B5: 45901 | C5: =TEXT(B5,"dddd") -> Monday | D5: Food | G5: 252 | H5: Krishna | J5: Vansh | K5: =SUMIFS(Income!$K:$K,Income!M:M,Expenses!J5,Income!$C:$C,"<="&Validations!$N$1) -> 45000 | L5: =SUMIFS(G:G,H:H,J5,B:B,"<="&Validations!$N$1) -> -80053.993 | M5: =K5-L5 -> 125053.99 | N5: =SUMIFS(Income!$K:$K,Income!$M:$M,Expenses!J5,Income!$C:$C,">="&Validations!$N$1) -> 0 | O5: =SUMIFS($G:$G,Expenses!$B:$B,">="&Validations!$N$1,Expenses!$H:$H,Expenses!J5,D:D,"<>"&"Salary") -> -31058 | P5: =N5-O5 -> 31058 | Q5: =($L$13+SUM($P$2:$P$5)+$P$9)/5-P5 -> 62389.606 | T5: Total | U5: =SUM(U2:U3) -> 600500
A6: =A5+1 -> 5 | B6: 45902 | C6: =TEXT(B6,"dddd") -> Tuesday | D6: Office expense | E6: Chai/Coffee | G6: 215 | H6: Rishabh | J6: Account-ArgosMob | K6: =SUMIFS(Income!$K:$K,Income!M:M,Expenses!J6,Income!$C:$C,"<="&Validations!$N$1) -> 1639501 | L6: =SUMIFS(G:G,H:H,J6,B:B,"<="&Validations!$N$1) -> 1639501 | M6: =K6-L6 -> 0 | N6: =SUMIFS(Income!$K:$K,Income!$M:$M,Expenses!J6,Income!$C:$C,">="&Validations!$N$1) -> 139600 | O6: =SUMIFS($G:$G,Expenses!$B:$B,">="&Validations!$N$1,Expenses!$H:$H,Expenses!J6,D:D,"<>"&"Salary") -> 4051.93 | P6: =N6-O6 -> 135548.07 | T6: Deficit/Surplus | U6: =L13-U5 -> -302944.13
A7: =A6+1 -> 6 | B7: 45902 | C7: =TEXT(B7,"dddd") -> Tuesday | D7: Electricity Recharge | E7: TS-618 | F7: TS-618 | G7: 2500 | H7: Rishabh | J7: Account-KiloWatt | K7: =SUMIFS(Income!$K:$K,Income!M:M,Expenses!J7,Income!$C:$C,"<="&Validations!$N$1) -> 0 | L7: =SUMIFS(G:G,H:H,J7,B:B,"<="&Validations!$N$1) -> 4.5297099e-14 | M7: =K7-L7 -> -4.5297099e-14 | N7: =SUMIFS(Income!$K:$K,Income!$M:$M,Expenses!J7,Income!$C:$C,">="&Validations!$N$1) -> 340010 | O7: =SUMIFS($G:$G,Expenses!$B:$B,">="&Validations!$N$1,Expenses!$H:$H,Expenses!J7) -> 200268.2 | P7: =N7-O7 -> 139741.8
A8: =A7+1 -> 7 | B8: 45902 | C8: =TEXT(B8,"dddd") -> Tuesday | D8: Marketing | E8: FB Ads | F8: FB Budget : 265425466458147 | G8: 20000 | H8: Chandan | J8: Cash | K8: =SUMIFS(Income!$K:$K,Income!M:M,Expenses!J8,Income!$C:$C,"<="&Validations!$N$1) -> 25000 | L8: =SUMIFS(G:G,H:H,J8,B:B,"<="&Validations!$N$1) -> 25000 | M8: =K8-L8 -> 0 | N8: =SUMIFS(Income!$K:$K,Income!$M:$M,Expenses!J8,Income!$C:$C,">="&Validations!$N$1) -> 0 | O8: =SUMIFS($G:$G,Expenses!$B:$B,">="&Validations!$N$1,Expenses!$H:$H,Expenses!J8) -> -22266 | P8: =N8-O8 -> 22266
A9: =A8+1 -> 8 | B9: 45902 | C9: =TEXT(B9,"dddd") -> Tuesday | D9: Office expense | E9: Maggi/Tea | G9: 428 | H9: Rishabh | J9: Dr Chadha | K9: =SUMIFS(Income!$K:$K,Income!M:M,Expenses!J9,Income!$C:$C,"<="&Validations!$N$1) -> 0 | L9: =SUMIFS(G:G,H:H,J9,B:B,"<="&Validations!$N$1) -> 0 | M9: =K9-L9 -> 0 | N9: =SUMIFS(Income!$K:$K,Income!$M:$M,Expenses!J9,Income!$C:$C,">="&Validations!$N$1) -> 0 | O9: =SUMIFS($G:$G,Expenses!$B:$B,">="&Validations!$N$1,Expenses!$H:$H,Expenses!J9,D:D,"<>"&"Loan",D:D,"<>"&"equity") -> -15529 | P9: =N9-O9 -> 15529 | Q9: =($L$13+SUM($P$2:$P$5)+$P$9)/5-P9 -> 77918.606
A10: =A9+1 -> 9 | B10: 45903 | C10: =TEXT(B10,"dddd") -> Wednesday | D10: Dialer recharge | G10: 500 | H10: Krishna | J10: Jitendra ji | K10: =SUMIFS(Income!$K:$K,Income!M:M,Expenses!J10,Income!$C:$C,"<="&Validations!$N$1) -> 0 | L10: =SUMIF(H:H,J10,G:G) -> -15529 | M10: =K10-L10 -> 15529
A11: =A10+1 -> 10 | B11: 45903 | C11: =TEXT(B11,"dddd") -> Wednesday | D11: Office expense | E11: Chai | G11: 30 | H11: Rishabh
A12: =A11+1 -> 11 | B12: 45903 | C12: =TEXT(B12,"dddd") -> Wednesday | D12: Office expense | F12: Printout | G12: 64 | H12: Chandan
A13: =A12+1 -> 12 | B13: 45903 | C13: =TEXT(B13,"dddd") -> Wednesday | D13: Office expense | E13: Coffee Sachets | G13: 96 | H13: Vansh | K13: Cash IN Hand | L13: =SUM(P6:P8) -> 297555.87
A14: =A13+1 -> 13 | B14: 45904 | C14: =TEXT(B14,"dddd") -> Thursday | D14: Office expense | E14: Prachi B'day Cake | G14: 685 | H14: Rishabh
A15: =A14+1 -> 14 | B15: 45905 | C15: =TEXT(B15,"dddd") -> Friday | D15: Office expense | E15: Fun | G15: 191 | H15: Krishna
A16: =A15+1 -> 15 | B16: 45908 | C16: =TEXT(B16,"dddd") -> Monday | D16: Office expense | E16: Tea | G16: 40 | H16: Rishabh
A17: =A16+1 -> 16 | B17: 45908 | C17: =TEXT(B17,"dddd") -> Monday | D17: Office expense | E17: Mouse | G17: 619 | H17: Krishna
A18: =A17+1 -> 17 | B18: 45909 | C18: =TEXT(B18,"dddd") -> Tuesday | D18: Office expense | E18: Chai/Coffee | G18: 105 | H18: Krishna | J18: Row Labels | K18: Sum of Amount
A19: =A18+1 -> 18 | B19: 45909 | C19: =TEXT(B19,"dddd") -> Tuesday | D19: Office expense | E19: Lunch | G19: 1134 | H19: Krishna | J19: Client Expenses | K19: 26070.76
A20: =A19+1 -> 19 | B20: 45909 | C20: =TEXT(B20,"dddd") -> Tuesday | D20: Office expense | E20: Coke lunch | G20: 140 | H20: Krishna | J20: Company Expense | K20: 2475
A21: =A20+1 -> 20 | B21: 45909 | C21: =TEXT(B21,"dddd") -> Tuesday | D21: Office expense | E21: Chai/Coffee | G21: 179 | H21: Vansh | J21: Dialer recharge | K21: 500
A22: =A21+1 -> 21 | B22: 45909 | C22: =TEXT(B22,"dddd") -> Tuesday | D22: Office expense | E22: Stationary | G22: 120 | H22: Krishna | J22: Electricity Recharge | K22: 5500
A23: =A22+1 -> 22 | B23: 45910 | C23: =TEXT(B23,"dddd") -> Wednesday | D23: Office expense | E23: Chai/Coffee | G23: 165 | H23: Krishna | J23: Fixed Expense | K23: 97653.98
A24: =A23+1 -> 23 | B24: 45910 | C24: =TEXT(B24,"dddd") -> Wednesday | D24: Salary | E24: Previous staff salary | F24: Paid to Aradhna | G24: 3000 | H24: Account-ArgosMob | J24: Food | K24: 5024.98
A25: =A24+1 -> 24 | B25: 45911 | C25: =TEXT(B25,"dddd") -> Thursday | D25: Office expense | E25: Chai/Coffee | G25: 120 | H25: Krishna | J25: Fun | K25: 180756.13
A26: =A25+1 -> 25 | B26: 45912 | C26: =TEXT(B26,"dddd") -> Friday | D26: Office expense | E26: Basket, colin, vim bar | G26: 385 | H26: Krishna | J26: Marketing | K26: 280500
A27: =A26+1 -> 26 | B27: 45915 | C27: =TEXT(B27,"dddd") -> Monday | D27: Office expense | E27: Chai/Coffee | G27: 165 | H27: Chandan | J27: Office expense | K27: 227225.39
A28: =A27+1 -> 27 | B28: 45916 | C28: =TEXT(B28,"dddd") -> Tuesday | D28: Office expense | E28: Mobile recharge | G28: 542 | H28: Krishna | J28: Operating Expenses | K28: 15000
A29: =A28+1 -> 28 | B29: 45916 | C29: =TEXT(B29,"dddd") -> Tuesday | D29: Office expense | E29: Chai/Coffee | G29: 545 | H29: Krishna | J29: Outsouce | K29: 5000
A30: =A29+1 -> 29 | B30: 45917 | C30: =TEXT(B30,"dddd") -> Wednesday | D30: Office expense | E30: Chai/Coffee | G30: 260 | H30: Vansh | J30: Salary | K30: 1424908.2
A31: =A30+1 -> 30 | B31: 45917 | C31: =TEXT(B31,"dddd") -> Wednesday | D31: Office expense | E31: KFC | G31: 667 | H31: Vansh | J31: Self Withdrawl | K31: -20187.6
A32: =A31+1 -> 31 | B32: 45918 | C32: =TEXT(B32,"dddd") -> Thursday | D32: Office expense | E32: Chai/Coffee | G32: 280 | H32: Krishna | J32: Grand Total | K32: 2250426.9
A33: =A32+1 -> 32 | B33: 45918 | C33: =TEXT(B33,"dddd") -> Thursday | D33: Office expense | E33: Electricity | G33: 1000 | H33: Krishna
A34: =A33+1 -> 33 | B34: 45918 | C34: =TEXT(B34,"dddd") -> Thursday | D34: Office expense | E34: Ice cream | G34: 260 | H34: Krishna
A35: =A34+1 -> 34 | B35: 45918 | C35: =TEXT(B35,"dddd") -> Thursday | D35: Office expense | E35: Internet | G35: 1005 | H35: Vansh
A36: =A35+1 -> 35 | B36: 45920 | C36: =TEXT(B36,"dddd") -> Saturday | D36: Bank Expenses | F36: Non-maintenance of AQB | G36: 1623.97 | H36: Account-ArgosMob
A37: =A36+1 -> 36 | B37: 45921 | C37: =TEXT(B37,"dddd") -> Sunday | D37: Fixed Expense | F37: Office 365: 2240920005 | G37: 179.66 | H37: Account-ArgosMob
A38: =A37+1 -> 37 | B38: 45922 | C38: =TEXT(B38,"dddd") -> Monday | D38: Office expense | E38: Maid-618 | G38: 1000 | H38: Chandan
A39: =A38+1 -> 38 | B39: 45922 | C39: =TEXT(B39,"dddd") -> Monday | D39: Self Funding | F39: Paid to Argomsob for rent | G39: 20000 | H39: Chandan
A40: =A39+1 -> 39 | B40: 45922 | C40: =TEXT(B40,"dddd") -> Monday | D40: Self Funding | F40: Received from Chandan | G40: -20000 | H40: Account-ArgosMob
...

Sheet Resource Performance
A1: Choose Resource-> | C1: Akansha
A2: 1 | B2: Salary | C2: 33000
A3: 2 | B3: Target(multiple) | C3: 15 | E3: Nov
A4: 3 | B4: Monthly Target | C4: =C3*C2 -> 495000
A5: 4 | B5: Total deal wins | C5: =COUNTIF('Order Book'!E:E,'Resource Performance'!C1) -> 1
A6: 5 | B6: Incentive | C6: 0.02
A9: Date | B9: Month | C9: Year | D9: Contract Wins | E9: Net | F9: Achieved % | G9: Month-On-Month | H9: Incentive
A10: 45901 | B10: =TEXT(DATE(C10,MONTH(A10),DAY(A10)),"MMMM") -> September | C10: 2025 | D10: =SUMIFS('Order Book'!K:K,'Order Book'!E:E,'Resource Performance'!$C$1,'Order Book'!C:C,">="&'Resource Performance'!A10,'Order Book'!C:C,"<="&EOMONTH('Resource Performance'!A10,0)) -> 0 | E10: =SUMIFS(Income!K:K,Income!F:F,'Resource Performance'!$C$1,Income!C:C,">="&'Resource Performance'!A10,Income!C:C,"<="&EOMONTH('Resource Performance'!A10,0)) -> 0 | F10: =D10/$C$4 -> 0 | H10: =IF(D10>=$C$4,$C$6*D10,0) -> 0
A11: =EOMONTH(A10,0)+1 -> 45931 | B11: =TEXT(DATE(C11,MONTH(A11),DAY(A11)),"MMMM") -> October | C11: 2025 | D11: =SUMIFS('Order Book'!K:K,'Order Book'!E:E,'Resource Performance'!$C$1,'Order Book'!C:C,">="&'Resource Performance'!A11,'Order Book'!C:C,"<="&EOMONTH('Resource Performance'!A11,0)) -> 0 | E11: =SUMIFS(Income!K:K,Income!F:F,'Resource Performance'!$C$1,Income!C:C,">="&'Resource Performance'!A11,Income!C:C,"<="&EOMONTH('Resource Performance'!A11,0)) -> 0 | F11: =D11/$C$4 -> 0 | G11: =IFERROR((D11/D10)-1,0) -> 0 | H11: =IF(D11>=$C$4,$C$6*D11,0) -> 0
A12: =EOMONTH(A11,0)+1 -> 45962 | B12: =TEXT(DATE(C12,MONTH(A12),DAY(A12)),"MMMM") -> November | C12: 2025 | D12: =SUMIFS('Order Book'!K:K,'Order Book'!E:E,'Resource Performance'!$C$1,'Order Book'!C:C,">="&'Resource Performance'!A12,'Order Book'!C:C,"<="&EOMONTH('Resource Performance'!A12,0)) -> 0 | E12: =SUMIFS(Income!K:K,Income!F:F,'Resource Performance'!$C$1,Income!C:C,">="&'Resource Performance'!A12,Income!C:C,"<="&EOMONTH('Resource Performance'!A12,0)) -> 0 | F12: =D12/$C$4 -> 0 | G12: =IFERROR((D12/D11)-1,0) -> 0 | H12: =IF(D12>=$C$4,$C$6*D12,0) -> 0
A13: =EOMONTH(A12,0)+1 -> 45992 | B13: =TEXT(DATE(C13,MONTH(A13),DAY(A13)),"MMMM") -> December | C13: 2025 | D13: =SUMIFS('Order Book'!K:K,'Order Book'!E:E,'Resource Performance'!$C$1,'Order Book'!C:C,">="&'Resource Performance'!A13,'Order Book'!C:C,"<="&EOMONTH('Resource Performance'!A13,0)) -> 0 | E13: =SUMIFS(Income!K:K,Income!F:F,'Resource Performance'!$C$1,Income!C:C,">="&'Resource Performance'!A13,Income!C:C,"<="&EOMONTH('Resource Performance'!A13,0)) -> 0 | F13: =D13/$C$4 -> 0 | G13: =IFERROR((D13/D12)-1,0) -> 0 | H13: =IF(D13>=$C$4,$C$6*D13,0) -> 0
A14: =EOMONTH(A13,0)+1 -> 46023 | B14: =TEXT(DATE(C14,MONTH(A14),DAY(A14)),"MMMM") -> January | C14: 2026 | D14: =SUMIFS('Order Book'!K:K,'Order Book'!E:E,'Resource Performance'!$C$1,'Order Book'!C:C,">="&'Resource Performance'!A14,'Order Book'!C:C,"<="&EOMONTH('Resource Performance'!A14,0)) -> 0 | E14: =SUMIFS(Income!K:K,Income!F:F,'Resource Performance'!$C$1,Income!C:C,">="&'Resource Performance'!A14,Income!C:C,"<="&EOMONTH('Resource Performance'!A14,0)) -> 0 | F14: =D14/$C$4 -> 0 | G14: =IFERROR((D14/D13)-1,0) -> 0 | H14: =IF(D14>=$C$4,$C$6*D14,0) -> 0
A15: =EOMONTH(A14,0)+1 -> 46054 | B15: =TEXT(DATE(C15,MONTH(A15),DAY(A15)),"MMMM") -> February | C15: 2026 | D15: =SUMIFS('Order Book'!K:K,'Order Book'!E:E,'Resource Performance'!$C$1,'Order Book'!C:C,">="&'Resource Performance'!A15,'Order Book'!C:C,"<="&EOMONTH('Resource Performance'!A15,0)) -> 206500 | E15: =SUMIFS(Income!K:K,Income!F:F,'Resource Performance'!$C$1,Income!C:C,">="&'Resource Performance'!A15,Income!C:C,"<="&EOMONTH('Resource Performance'!A15,0)) -> 82600 | F15: =D15/$C$4 -> 0.41717172 | G15: =IFERROR((D15/D14)-1,0) -> 0 | H15: =IF(D15>=$C$4,$C$6*D15,0) -> 0
A16: =EOMONTH(A15,0)+1 -> 46082 | B16: =TEXT(DATE(C16,MONTH(A16),DAY(A16)),"MMMM") -> March | C16: 2026 | D16: =SUMIFS('Order Book'!K:K,'Order Book'!E:E,'Resource Performance'!$C$1,'Order Book'!C:C,">="&'Resource Performance'!A16,'Order Book'!C:C,"<="&EOMONTH('Resource Performance'!A16,0)) -> 0 | E16: =SUMIFS(Income!K:K,Income!F:F,'Resource Performance'!$C$1,Income!C:C,">="&'Resource Performance'!A16,Income!C:C,"<="&EOMONTH('Resource Performance'!A16,0)) -> 0 | F16: =D16/$C$4 -> 0 | G16: =IFERROR((D16/D15)-1,0) -> -1 | H16: =IF(D16>=$C$4,$C$6*D16,0) -> 0
A17: =EOMONTH(A16,0)+1 -> 46113 | B17: =TEXT(DATE(C17,MONTH(A17),DAY(A17)),"MMMM") -> April | C17: 2026 | D17: =SUMIFS('Order Book'!K:K,'Order Book'!E:E,'Resource Performance'!$C$1,'Order Book'!C:C,">="&'Resource Performance'!A17,'Order Book'!C:C,"<="&EOMONTH('Resource Performance'!A17,0)) -> 0 | E17: =SUMIFS(Income!K:K,Income!F:F,'Resource Performance'!$C$1,Income!C:C,">="&'Resource Performance'!A17,Income!C:C,"<="&EOMONTH('Resource Performance'!A17,0)) -> 0 | F17: =D17/$C$4 -> 0 | G17: =IFERROR((D17/D16)-1,0) -> 0 | H17: =IF(D17>=$C$4,$C$6*D17,0) -> 0
A18: =EOMONTH(A17,0)+1 -> 46143 | B18: =TEXT(DATE(C18,MONTH(A18),DAY(A18)),"MMMM") -> May | C18: 2026 | D18: =SUMIFS('Order Book'!K:K,'Order Book'!E:E,'Resource Performance'!$C$1,'Order Book'!C:C,">="&'Resource Performance'!A18,'Order Book'!C:C,"<="&EOMONTH('Resource Performance'!A18,0)) -> 0 | E18: =SUMIFS(Income!K:K,Income!F:F,'Resource Performance'!$C$1,Income!C:C,">="&'Resource Performance'!A18,Income!C:C,"<="&EOMONTH('Resource Performance'!A18,0)) -> 0 | F18: =D18/$C$4 -> 0 | G18: =IFERROR((D18/D17)-1,0) -> 0 | H18: =IF(D18>=$C$4,$C$6*D18,0) -> 0
A19: =EOMONTH(A18,0)+1 -> 46174 | B19: =TEXT(DATE(C19,MONTH(A19),DAY(A19)),"MMMM") -> June | C19: 2026 | D19: =SUMIFS('Order Book'!K:K,'Order Book'!E:E,'Resource Performance'!$C$1,'Order Book'!C:C,">="&'Resource Performance'!A19,'Order Book'!C:C,"<="&EOMONTH('Resource Performance'!A19,0)) -> 0 | E19: =SUMIFS(Income!K:K,Income!F:F,'Resource Performance'!$C$1,Income!C:C,">="&'Resource Performance'!A19,Income!C:C,"<="&EOMONTH('Resource Performance'!A19,0)) -> 0 | F19: =D19/$C$4 -> 0 | G19: =IFERROR((D19/D18)-1,0) -> 0 | H19: =IF(D19>=$C$4,$C$6*D19,0) -> 0
A20: =EOMONTH(A19,0)+1 -> 46204 | B20: =TEXT(DATE(C20,MONTH(A20),DAY(A20)),"MMMM") -> July | C20: 2026 | D20: =SUMIFS('Order Book'!K:K,'Order Book'!E:E,'Resource Performance'!$C$1,'Order Book'!C:C,">="&'Resource Performance'!A20,'Order Book'!C:C,"<="&EOMONTH('Resource Performance'!A20,0)) -> 0 | E20: =SUMIFS(Income!K:K,Income!F:F,'Resource Performance'!$C$1,Income!C:C,">="&'Resource Performance'!A20,Income!C:C,"<="&EOMONTH('Resource Performance'!A20,0)) -> 0 | F20: =D20/$C$4 -> 0 | G20: =IFERROR((D20/D19)-1,0) -> 0 | H20: =IF(D20>=$C$4,$C$6*D20,0) -> 0
A21: =EOMONTH(A20,0)+1 -> 46235 | B21: =TEXT(DATE(C21,MONTH(A21),DAY(A21)),"MMMM") -> August | C21: 2026 | D21: =SUMIFS('Order Book'!K:K,'Order Book'!E:E,'Resource Performance'!$C$1,'Order Book'!C:C,">="&'Resource Performance'!A21,'Order Book'!C:C,"<="&EOMONTH('Resource Performance'!A21,0)) -> 0 | E21: =SUMIFS(Income!K:K,Income!F:F,'Resource Performance'!$C$1,Income!C:C,">="&'Resource Performance'!A21,Income!C:C,"<="&EOMONTH('Resource Performance'!A21,0)) -> 0 | F21: =D21/$C$4 -> 0 | G21: =IFERROR((D21/D20)-1,0) -> 0 | H21: =IF(D21>=$C$4,$C$6*D21,0) -> 0
A22: =EOMONTH(A21,0)+1 -> 46266 | B22: =TEXT(DATE(C22,MONTH(A22),DAY(A22)),"MMMM") -> September | C22: 2026 | D22: =SUMIFS('Order Book'!K:K,'Order Book'!E:E,'Resource Performance'!$C$1,'Order Book'!C:C,">="&'Resource Performance'!A22,'Order Book'!C:C,"<="&EOMONTH('Resource Performance'!A22,0)) -> 0 | E22: =SUMIFS(Income!K:K,Income!F:F,'Resource Performance'!$C$1,Income!C:C,">="&'Resource Performance'!A22,Income!C:C,"<="&EOMONTH('Resource Performance'!A22,0)) -> 0 | F22: =D22/$C$4 -> 0 | G22: =IFERROR((D22/D21)-1,0) -> 0 | H22: =IF(D22>=$C$4,$C$6*D22,0) -> 0
... A25: =EOMONTH(A24,0)+1 -> 46357 | B25: =TEXT(DATE(C25,MONTH(A25),DAY(A25)),"MMMM") -> December | C25: 2026 | D25: =SUMIFS('Order Book'!K:K,'Order Book'!E:E,'Resource Performance'!$C$1,'Order Book'!C:C,">="&'Resource Performance'!A25,'Order Book'!C:C,"<="&EOMONTH('Resource Performance'!A25,0)) -> 0 | E25: =SUMIFS(Income!K:K,Income!F:F,'Resource Performance'!$C$1,Income!C:C,">="&'Resource Performance'!A25,Income!C:C,"<="&EOMONTH('Resource Performance'!A25,0)) -> 0 | F25: =D25/$C$4 -> 0 | G25: =IFERROR((D25/D24)-1,0) -> 0 | H25: =IF(D25>=$C$4,$C$6*D25,0) -> 0
C27: Total - > | D27: =SUM(D10:D26) -> 206500 | E27: =SUM(E10:E26) -> 82600 | H27: =SUM(H10:H26) -> 0

Sheet Balance Amount
A2: Row Labels | B2: Sum of Contract Value(INR) | C2: Sum of Received(INR) | D2: Sum of Balance(INR)
A3: AI LMS Portal | B3: 400000 | C3: 100000 | D3: 300000
A4: Employee India | B4: 250000 | C4: 50000 | D4: 200000
A5: SK Car Finance | B5: 220000 | C5: 50000 | D5: 170000
A6: Farm produce selling app | B6: 190000 | C6: 57000 | D6: 133000
A7: Digital Poster App | B7: 150000 | C7: 35000 | D7: 115000
A8: Taxi App | B8: 104000 | C8: 10000 | D8: 94000
A9: NGK | B9: 225000 | C9: 142111.32 | D9: 82888.68
A10: Indgrocart | B10: 80000 | C10: 0 | D10: 80000
A11: MediConnect | B11: 600000 | C11: 520001 | D11: 79999
A12: Easy Rasta | B12: 150000 | C12: 75000 | D12: 75000
A13: Soya Products-Ecom | B13: 85000 | C13: 11000 | D13: 74000
A14: Local Market Online | B14: 200000 | C14: 140000 | D14: 60000
... A39: Grand Total | B39: 4408000 | C39: 2561612.3 | D39: 1846387.7

Sheet Order Book
A1: Sno | B1: Day | C1: Sale Date | D1: Project Type | E1: Resource | F1: Currency | G1: Project Manager | H1: Project Name | I1: Client Name | J1: Country | K1: Contract Value | L1: Exchange | M1: Contract Value(INR) | N1: Received(INR) | O1: Balance(INR) | P1: Column1 | Q1: Company Financial Snapshot and Next 1-year Projections | T1: Project Manager | U1: Count
A2: 1 | B2: =TEXT(Table1[[#This Row],[Sale Date]], "dddd") -> Monday | C2: 45908 | D2: Android+IOS App | E2: N/A | F2: INR | G2: Chandan+Rishabh | H2: Employee India | I2: Taufeeq | J2: India | K2: 250000 | L2: 1 | M2: =Table1[[#This Row],[Exchange]]*Table1[[#This Row],[Contract Value]] -> 250000 | N2: =SUMIFS(Income!K:K,Income!G:G,Table1[[#This Row],[Project Name]],Income!E:E,Table1[[#This Row],[Project Type]],Income!H:H,Table1[[#This Row],[Client Name]]) -> 50000 | O2: =Table1[[#This Row],[Contract Value(INR)]]-Table1[[#This Row],[Received(INR)]] -> 200000 | Q2: Total Contract | R2: =SUM(M:M) -> 4707510 | T2: Chandan+Rishabh | U2: =COUNTIF(G:G,T2) -> 14
A3: =A2+1 -> 2 | B3: =TEXT(Table1[[#This Row],[Sale Date]], "dddd") -> Tuesday | C3: 45916 | D3: Android App | E3: Prachi Lohani | F3: INR | G3: Vansh+Krishna | H3: Makroo | I3: Umar | J3: India | K3: 60000 | L3: 1 | M3: =Table1[[#This Row],[Exchange]]*Table1[[#This Row],[Contract Value]] -> 60000 | N3: =SUMIFS(Income!K:K,Income!G:G,Table1[[#This Row],[Project Name]],Income!E:E,Table1[[#This Row],[Project Type]],Income!H:H,Table1[[#This Row],[Client Name]]) -> 60000 | O3: =Table1[[#This Row],[Contract Value(INR)]]-Table1[[#This Row],[Received(INR)]] -> 0 | Q3: Total Received | R3: =SUM(N:N) -> 2772222.3 | T3: Vansh+Krishna | U3: =COUNTIF(G:G,T3) -> 23
A4: =A3+1 -> 3 | B4: =TEXT(Table1[[#This Row],[Sale Date]], "dddd") -> Sunday | C4: 45921 | D4: AI | E4: Parul Sandilya | F4: INR | G4: Chandan+Rishabh | H4: AI | I4: Sushil | J4: India | K4: 40000 | L4: 1 | M4: =Table1[[#This Row],[Exchange]]*Table1[[#This Row],[Contract Value]] -> 40000 | N4: =SUMIFS(Income!K:K,Income!G:G,Table1[[#This Row],[Project Name]],Income!E:E,Table1[[#This Row],[Project Type]],Income!H:H,Table1[[#This Row],[Client Name]]) -> 40000 | O4: =Table1[[#This Row],[Contract Value(INR)]]-Table1[[#This Row],[Received(INR)]] -> 0 | Q4: Total Balance | R4: =R2-R3 -> 1935287.7
A5: =A4+1 -> 4 | B5: =TEXT(Table1[[#This Row],[Sale Date]], "dddd") -> Friday | C5: 45926 | D5: Website | E5: N/A | F5: INR | G5: Vansh+Krishna | H5: Brandloomi | I5: Anuj | J5: India | K5: 15000 | L5: 1 | M5: =Table1[[#This Row],[Exchange]]*Table1[[#This Row],[Contract Value]] -> 15000 | N5: =SUMIFS(Income!K:K,Income!G:G,Table1[[#This Row],[Project Name]],Income!E:E,Table1[[#This Row],[Project Type]],Income!H:H,Table1[[#This Row],[Client Name]]) -> 15000 | O5: =Table1[[#This Row],[Contract Value(INR)]]-Table1[[#This Row],[Received(INR)]] -> 0
A6: =A5+1 -> 5 | B6: =TEXT(Table1[[#This Row],[Sale Date]], "dddd") -> Friday | C6: 45926 | D6: Website | E6: N/A | F6: INR | G6: Chandan+Rishabh | H6: Healthy Manushya | I6: Arun Sharma | J6: India | K6: 25000 | L6: 1 | M6: =Table1[[#This Row],[Exchange]]*Table1[[#This Row],[Contract Value]] -> 25000 | N6: =SUMIFS(Income!K:K,Income!G:G,Table1[[#This Row],[Project Name]],Income!E:E,Table1[[#This Row],[Project Type]],Income!H:H,Table1[[#This Row],[Client Name]]) -> 25000 | O6: =Table1[[#This Row],[Contract Value(INR)]]-Table1[[#This Row],[Received(INR)]] -> 0 | T6: Total | U6: =SUM(U2:U4) -> 37
A7: =A6+1 -> 6 | B7: =TEXT(Table1[[#This Row],[Sale Date]], "dddd") -> Friday | C7: 45926 | D7: Android+IOS App | E7: N/A | F7: INR | G7: Vansh+Krishna | H7: Indgrocart | I7: Rajesh | J7: India | K7: 70000 | L7: 1 | M7: =Table1[[#This Row],[Exchange]]*Table1[[#This Row],[Contract Value]] -> 70000 | N7: =SUMIFS(Income!K:K,Income!G:G,Table1[[#This Row],[Project Name]],Income!E:E,Table1[[#This Row],[Project Type]],Income!H:H,Table1[[#This Row],[Client Name]]) -> 0 | O7: =Table1[[#This Row],[Contract Value(INR)]]-Table1[[#This Row],[Received(INR)]] -> 70000 | Q7: Start Date | R7: 45901
A8: =A7+1 -> 7 | B8: =TEXT(Table1[[#This Row],[Sale Date]], "dddd") -> Wednesday | C8: 45931 | D8: Android+IOS App+Website | E8: Prachi Lohani | F8: INR | G8: Vansh+Krishna | H8: MediConnect | I8: Brij | J8: India | K8: 600000 | L8: 1 | M8: =Table1[[#This Row],[Exchange]]*Table1[[#This Row],[Contract Value]] -> 600000 | N8: =SUMIFS(Income!K:K,Income!G:G,Table1[[#This Row],[Project Name]],Income!E:E,Table1[[#This Row],[Project Type]],Income!H:H,Table1[[#This Row],[Client Name]]) -> 520001 | O8: =Table1[[#This Row],[Contract Value(INR)]]-Table1[[#This Row],[Received(INR)]] -> 79999 | Q8: Today | R8: =TODAY() -> 46093
A9: =A8+1 -> 8 | B9: =TEXT(Table1[[#This Row],[Sale Date]], "dddd") -> Friday | C9: 45940 | D9: Android+IOS App | E9: Prachi Lohani | F9: INR | G9: Vansh+Krishna | H9: Fornix | I9: Venket | J9: India | K9: 160000 | L9: 1 | M9: =Table1[[#This Row],[Exchange]]*Table1[[#This Row],[Contract Value]] -> 160000 | N9: =SUMIFS(Income!K:K,Income!G:G,Table1[[#This Row],[Project Name]],Income!E:E,Table1[[#This Row],[Project Type]],Income!H:H,Table1[[#This Row],[Client Name]]) -> 160000 | O9: =Table1[[#This Row],[Contract Value(INR)]]-Table1[[#This Row],[Received(INR)]] -> 0 | Q9: Days Passed Business Operation | R9: =R8-R7 -> 192
A10: =A9+1 -> 9 | B10: =TEXT(Table1[[#This Row],[Sale Date]], "dddd") -> Tuesday | C10: 45944 | D10: AI | E10: N/A | F10: INR | G10: Chandan+Rishabh | H10: Stenna | I10: Madhur Goel | J10: India | K10: 20000 | L10: 1 | M10: =Table1[[#This Row],[Exchange]]*Table1[[#This Row],[Contract Value]] -> 20000 | N10: =SUMIFS(Income!K:K,Income!G:G,Table1[[#This Row],[Project Name]],Income!E:E,Table1[[#This Row],[Project Type]],Income!H:H,Table1[[#This Row],[Client Name]]) -> 20000 | O10: =Table1[[#This Row],[Contract Value(INR)]]-Table1[[#This Row],[Received(INR)]] -> 0 | Q10: Number of Projects | R10: =COUNTA(A:A)-1 -> 39
A11: =A10+1 -> 10 | B11: =TEXT(Table1[[#This Row],[Sale Date]], "dddd") -> Thursday | C11: 45946 | D11: Android+IOS App | E11: Parul Sandilya | F11: INR | G11: Vansh+Krishna | H11: Bla-Bla | I11: Prem Reddy | J11: India | K11: 108000 | L11: 1 | M11: =Table1[[#This Row],[Exchange]]*Table1[[#This Row],[Contract Value]] -> 108000 | N11: =SUMIFS(Income!K:K,Income!G:G,Table1[[#This Row],[Project Name]],Income!E:E,Table1[[#This Row],[Project Type]],Income!H:H,Table1[[#This Row],[Client Name]]) -> 73000 | O11: =Table1[[#This Row],[Contract Value(INR)]]-Table1[[#This Row],[Received(INR)]] -> 35000 | Q11: Days/Project | R11: =R9/R10 -> 4.9230769
A12: =A11+1 -> 11 | B12: =TEXT(Table1[[#This Row],[Sale Date]], "dddd") -> Friday | C12: 45947 | D12: Android+IOS App | E12: Parul Sandilya | F12: INR | G12: Vansh+Krishna | H12: Bhardwaj hospital | I12: Dr Arun | J12: India | K12: 75000 | L12: 1 | M12: =Table1[[#This Row],[Exchange]]*Table1[[#This Row],[Contract Value]] -> 75000 | N12: =SUMIFS(Income!K:K,Income!G:G,Table1[[#This Row],[Project Name]],Income!E:E,Table1[[#This Row],[Project Type]],Income!H:H,Table1[[#This Row],[Client Name]]) -> 52500 | O12: =Table1[[#This Row],[Contract Value(INR)]]-Table1[[#This Row],[Received(INR)]] -> 22500 | Q12: Annual Pojects Projection | R12: =365/R11 -> 74.140625
A13: =A12+1 -> 12 | B13: =TEXT(Table1[[#This Row],[Sale Date]], "dddd") -> Friday | C13: 45947 | D13: Android+IOS App | E13: Parul Sandilya | F13: INR | G13: Vansh+Krishna | H13: Eco Volt Solar | I13: Kuldeep | J13: India | K13: 100000 | L13: 1 | M13: =Table1[[#This Row],[Exchange]]*Table1[[#This Row],[Contract Value]] -> 100000 | N13: =SUMIFS(Income!K:K,Income!G:G,Table1[[#This Row],[Project Name]],Income!E:E,Table1[[#This Row],[Project Type]],Income!H:H,Table1[[#This Row],[Client Name]]) -> 70000 | O13: =Table1[[#This Row],[Contract Value(INR)]]-Table1[[#This Row],[Received(INR)]] -> 30000 | Q13: Average Contact Value | R13: =R2/R10 -> 120705.38
A14: =A13+1 -> 13 | B14: =TEXT(Table1[[#This Row],[Sale Date]], "dddd") -> Wednesday | C14: 45959 | D14: Website | E14: N/A | F14: INR | G14: Vansh+Krishna | H14: Makroo | I14: Umar | J14: India | K14: 12500 | L14: 1 | M14: =Table1[[#This Row],[Exchange]]*Table1[[#This Row],[Contract Value]] -> 12500 | N14: =SUMIFS(Income!K:K,Income!G:G,Table1[[#This Row],[Project Name]],Income!E:E,Table1[[#This Row],[Project Type]],Income!H:H,Table1[[#This Row],[Client Name]]) -> 12500 | O14: =Table1[[#This Row],[Contract Value(INR)]]-Table1[[#This Row],[Received(INR)]] -> 0 | Q14: Next 1 year Contract Value Projection | R14: =R13*R12 -> 8949172.7
A15: =A14+1 -> 14 | B15: =TEXT(Table1[[#This Row],[Sale Date]], "dddd") -> Monday | C15: 45964 | D15: Android+IOS App | E15: Parul Sandilya | F15: INR | G15: Vansh+Krishna | H15: Soya Products-Ecom | I15: M M Mishra | J15: India | K15: 85000 | L15: 1 | M15: =Table1[[#This Row],[Exchange]]*Table1[[#This Row],[Contract Value]] -> 85000 | N15: =SUMIFS(Income!K:K,Income!G:G,Table1[[#This Row],[Project Name]],Income!E:E,Table1[[#This Row],[Project Type]],Income!H:H,Table1[[#This Row],[Client Name]]) -> 11000 | O15: =Table1[[#This Row],[Contract Value(INR)]]-Table1[[#This Row],[Received(INR)]] -> 74000
A16: =A15+1 -> 15 | B16: =TEXT(Table1[[#This Row],[Sale Date]], "dddd") -> Wednesday | C16: 45973 | D16: Android+IOS App | E16: N/A | F16: INR | G16: Chandan+Rishabh | H16: Degree India | I16: Taufeeq | J16: India | K16: 30000 | L16: 1 | M16: =Table1[[#This Row],[Exchange]]*Table1[[#This Row],[Contract Value]] -> 30000 | N16: =SUMIFS(Income!K:K,Income!G:G,Table1[[#This Row],[Project Name]],Income!E:E,Table1[[#This Row],[Project Type]],Income!H:H,Table1[[#This Row],[Client Name]]) -> 30000 | O16: =Table1[[#This Row],[Contract Value(INR)]]-Table1[[#This Row],[Received(INR)]] -> 0 | Q16: Start Date | R16: 45901
A17: =A16+1 -> 16 | B17: =TEXT(Table1[[#This Row],[Sale Date]], "dddd") -> Friday | C17: 45975 | D17: Website | E17: N/A | F17: INR | G17: Chandan+Rishabh | H17: Enlightify | I17: Apoorv | J17: India | K17: 25000 | L17: 1 | M17: =Table1[[#This Row],[Exchange]]*Table1[[#This Row],[Contract Value]] -> 25000 | N17: =SUMIFS(Income!K:K,Income!G:G,Table1[[#This Row],[Project Name]],Income!E:E,Table1[[#This Row],[Project Type]],Income!H:H,Table1[[#This Row],[Client Name]]) -> 7000 | O17: =Table1[[#This Row],[Contract Value(INR)]]-Table1[[#This Row],[Received(INR)]] -> 18000 | Q17: Calculation Date | R17: 46087
A18: =A17+1 -> 17 | B18: =TEXT(Table1[[#This Row],[Sale Date]], "dddd") -> Saturday | C18: 45976 | D18: Android+IOS App | E18: Haider | F18: INR | G18: Chandan+Rishabh | H18: Easy Rasta | I18: Dennis Anthony | J18: India | K18: 150000 | L18: 1 | M18: =Table1[[#This Row],[Exchange]]*Table1[[#This Row],[Contract Value]] -> 150000 | N18: =SUMIFS(Income!K:K,Income!G:G,Table1[[#This Row],[Project Name]],Income!E:E,Table1[[#This Row],[Project Type]],Income!H:H,Table1[[#This Row],[Client Name]]) -> 75000 | O18: =Table1[[#This Row],[Contract Value(INR)]]-Table1[[#This Row],[Received(INR)]] -> 75000 | Q18: Marketing Project Aquired | R18: =COUNTIF(E:E,"Prachi Lohani")+COUNTIF(E:E,"Parul Sandilya")++COUNTIF(E:E,"Haider") -> 21
A19: =A18+1 -> 18 | B19: =TEXT(Table1[[#This Row],[Sale Date]], "dddd") -> Thursday | C19: 45981 | D19: Android+IOS App | E19: Parul Sandilya | F19: INR | G19: Vansh+Krishna | H19: FitLeap | I19: Babu Raj | J19: India | K19: 160000 | L19: 1 | M19: =Table1[[#This Row],[Exchange]]*Table1[[#This Row],[Contract Value]] -> 160000 | N19: =SUMIFS(Income!K:K,Income!G:G,Table1[[#This Row],[Project Name]],Income!E:E,Table1[[#This Row],[Project Type]],Income!H:H,Table1[[#This Row],[Client Name]]) -> 120000 | O19: =Table1[[#This Row],[Contract Value(INR)]]-Table1[[#This Row],[Received(INR)]] -> 40000 | Q19: Total FB Budget till 02-02-2026 | R19: 276016.16
A20: =A19+1 -> 19 | B20: =TEXT(Table1[[#This Row],[Sale Date]], "dddd") -> Friday | C20: 45982 | D20: Android+IOS App | E20: Haider | F20: INR | G20: Vansh+Krishna | H20: SK Car Finance | I20: Prateek Srivastava | J20: India | K20: 220000 | L20: 1 | M20: =Table1[[#This Row],[Exchange]]*Table1[[#This Row],[Contract Value]] -> 220000 | N20: =SUMIFS(Income!K:K,Income!G:G,Table1[[#This Row],[Project Name]],Income!E:E,Table1[[#This Row],[Project Type]],Income!H:H,Table1[[#This Row],[Client Name]]) -> 50000 | O20: =Table1[[#This Row],[Contract Value(INR)]]-Table1[[#This Row],[Received(INR)]] -> 170000 | Q20: Office Fixed Cost | R20: =50000*_xlfn.DAYS(R17,R16)/30 -> 310000 | S20: Taken 50k fixed cost for office
A21: =A20+1 -> 20 | B21: =TEXT(Table1[[#This Row],[Sale Date]], "dddd") -> Tuesday | C21: 45986 | D21: Android+IOS App | E21: N/A | F21: INR | G21: Chandan+Rishabh | H21: NGK | I21: Strini Naidu | J21: South Africa | K21: 2500 | L21: 90 | M21: =Table1[[#This Row],[Exchange]]*Table1[[#This Row],[Contract Value]] -> 225000 | N21: =SUMIFS(Income!K:K,Income!G:G,Table1[[#This Row],[Project Name]],Income!E:E,Table1[[#This Row],[Project Type]],Income!H:H,Table1[[#This Row],[Client Name]]) -> 142111.32 | O21: =Table1[[#This Row],[Contract Value(INR)]]-Table1[[#This Row],[Received(INR)]] -> 82888.68 | Q21: Marketing Salaries
